[collect_callgraphs] PID = 5901
[collect_callgraphs] Collecting data for IoTFishtank
Encountered error: Traceback (most recent call last):
  File "/home/marcela/Research/lib-isolation/iot-app-analysis/callgraph-analysis/python35/Lib/configparser.py", line 1135, in _unify_values
    sectiondict = self._sections[section]
KeyError: 'general'

During handling of the above exception, another exception occurred:

Traceback (most recent call last):
  File "/home/marcela/Research/lib-isolation/iot-app-analysis/callgraph-analysis/tracer.py", line 275, in _runctx
    exec(cmd, globs, locs)
  File "../apps/visual-py3/IoTFishtank/IoTFishtank.py", line 6, in <module>
    import FishTank
  File "../apps/visual-py3/IoTFishtank/FishTank.py", line 6, in <module>
    import FoodStore
  File "../apps/visual-py3/IoTFishtank/FoodStore.py", line 2, in <module>
    import Config
  File "../apps/visual-py3/IoTFishtank/Config.py", line 6, in <module>
    path = config.get('general', 'path')
  File "/home/marcela/Research/lib-isolation/iot-app-analysis/callgraph-analysis/python35/Lib/configparser.py", line 778, in get
    d = self._unify_values(section, vars)
  File "/home/marcela/Research/lib-isolation/iot-app-analysis/callgraph-analysis/python35/Lib/configparser.py", line 1138, in _unify_values
    raise NoSectionError(section)
configparser.NoSectionError: No section: 'general'

[collect_callgraphs] Collecting data for pi_home_surveillance
Encountered error: Traceback (most recent call last):
  File "/home/marcela/Research/lib-isolation/iot-app-analysis/callgraph-analysis/tracer.py", line 275, in _runctx
    exec(cmd, globs, locs)
  File "../apps/visual-py3/pi_home_surveillance/pi_home_surveillance.py", line 8, in <module>
    from picamera.array import PiRGBArray
  File "/tmp/libs/picamera/picamera/__init__.py", line 72, in <module>
    from picamera.exc import (
  File "/tmp/libs/picamera/picamera/exc.py", line 41, in <module>
    import picamera.mmal as mmal
  File "/tmp/libs/picamera/picamera/mmal.py", line 47, in <module>
    _lib = ct.CDLL('libmmal.so')
  File "/home/marcela/Research/lib-isolation/iot-app-analysis/callgraph-analysis/python35/Lib/ctypes/__init__.py", line 351, in __init__
    self._handle = _dlopen(self._name, mode)
OSError: libmmal.so: cannot open shared object file: No such file or directory

[collect_callgraphs] Collecting data for RPiLaserSecurity.py
Encountered error: Traceback (most recent call last):
  File "/home/marcela/Research/lib-isolation/iot-app-analysis/callgraph-analysis/tracer.py", line 275, in _runctx
    exec(cmd, globs, locs)
  File "../apps/visual-py3/RPiLaserSecurity.py", line 10, in <module>
    import RPi.GPIO as GPIO  #we need this so we can access the pins
  File "/tmp/libs/RPi.GPIO/RPi/GPIO/__init__.py", line 23, in <module>
    from RPi._GPIO import *
RuntimeError: This module can only be run on a Raspberry Pi!

[collect_callgraphs] Collecting data for PiScream.py
Encountered error: Traceback (most recent call last):
  File "/home/marcela/Research/lib-isolation/iot-app-analysis/callgraph-analysis/tracer.py", line 275, in _runctx
    exec(cmd, globs, locs)
  File "../apps/visual-py3/PiScream.py", line 4, in <module>
    import picamera
  File "/tmp/libs/picamera/picamera/__init__.py", line 72, in <module>
    from picamera.exc import (
  File "/tmp/libs/picamera/picamera/exc.py", line 41, in <module>
    import picamera.mmal as mmal
  File "/tmp/libs/picamera/picamera/mmal.py", line 47, in <module>
    _lib = ct.CDLL('libmmal.so')
  File "/home/marcela/Research/lib-isolation/iot-app-analysis/callgraph-analysis/python35/Lib/ctypes/__init__.py", line 351, in __init__
    self._handle = _dlopen(self._name, mode)
OSError: libmmal.so: cannot open shared object file: No such file or directory

[collect_callgraphs] Collecting data for RPiPhotobooth
Downloading _tkinter
Traceback (most recent call last):
  File "/home/marcela/Research/lib-isolation/iot-app-analysis/callgraph-analysis/tracer.py", line 275, in _runctx
    exec(cmd, globs, locs)
  File "../apps/visual-py3/RPiPhotobooth/RPiPhotobooth.py", line 9, in <module>
    from tkkb import Tkkb
  File "../apps/visual-py3/RPiPhotobooth/tkkb.py", line 1, in <module>
    from tkinter import *
  File "/home/marcela/Research/lib-isolation/iot-app-analysis/callgraph-analysis/python35/Lib/tkinter/__init__.py", line 35, in <module>
    import _tkinter # If this fails your Python may not be configured for Tk
ImportError: No module named '_tkinter'

During handling of the above exception, another exception occurred:

Traceback (most recent call last):
  File "collect-callgraphs.py", line 83, in <module>
    tr.start_tracer()
  File "/home/marcela/Research/lib-isolation/iot-app-analysis/callgraph-analysis/tracer.py", line 318, in start_tracer
    self._runctx(code, globs, None)
  File "/home/marcela/Research/lib-isolation/iot-app-analysis/callgraph-analysis/tracer.py", line 291, in _runctx
    subprocess.check_output(["pip3", "install", "-qq", "--no-compile", "-t", "../libs/"+lib, lib])
  File "/home/marcela/Research/lib-isolation/iot-app-analysis/callgraph-analysis/python35/Lib/subprocess.py", line 316, in check_output
    **kwargs).stdout
  File "/home/marcela/Research/lib-isolation/iot-app-analysis/callgraph-analysis/python35/Lib/subprocess.py", line 398, in run
    output=stdout, stderr=stderr)
subprocess.CalledProcessError: Command '['pip3', 'install', '-qq', '--no-compile', '-t', '../libs/_tkinter', '_tkinter']' returned non-zero exit status 1
